<?xml version="1.0" encoding="utf-8"?>
<!-- This URDF was automatically created by SolidWorks to URDF Exporter! Originally created by Stephen Brawner (brawner@gmail.com) 
     Commit Version: 1.6.0-4-g7f85cfe  Build Version: 1.6.7995.38578
     For more information, please see http://wiki.ros.org/sw_urdf_exporter -->
<robot
  name="A1_dual">
  <mujoco>
    <compiler meshdir="../../meshes/A1_dual/" balanceinertia="true" discardvisual="false" />
  </mujoco>

  <!-- Virtual root link for KDL compatibility -->
  <link name="world"/>

  <!-- Virtual root joint -->
  <joint name="world_to_base" type="fixed">
    <parent link="world"/>
    <child link="base_link"/>
    <origin xyz="0 0 0" rpy="0 0 0"/>
  </joint>

  <link
    name="base_link">
    <inertial>
      <origin
        xyz="0.0010220177563175 0.0098303072982387 0.183397090016791"
        rpy="0 0 0" />
      <mass
        value="64.4643570459224" />
      <inertia
        ixx="4.29797927001766"
        ixy="7.03998162475598E-07"
        ixz="-0.00276639447242792"
        iyy="3.97809452117849"
        iyz="-1.5197115178996E-07"
        izz="0.744626161704809" />
    </inertial>
    <visual>
      <origin
        xyz="0 0 0"
        rpy="0 0 0" />
      <geometry>
        <mesh
          filename="package://onero_description/meshes/A1_dual/base_link.STL" />
      </geometry>
      <material
        name="">
        <color
          rgba="0.776470588235294 0.756862745098039 0.737254901960784 1" />
      </material>
    </visual>
    <collision>
      <origin
        xyz="0 0 0"
        rpy="0 0 0" />
      <geometry>
        <mesh
          filename="package://onero_description/meshes/A1_dual/base_link.STL" />
      </geometry>
    </collision>
  </link>
  <link
    name="right_base_link">
    <inertial>
      <origin
        xyz="-2.13344287977907E-05 -5.52115991738867E-05 0.0171427944780142"
        rpy="0 0 0" />
      <mass
        value="0.401649629361067" />
      <inertia
        ixx="0.000237179582900665"
        ixy="-1.22282445342032E-07"
        ixz="-1.58190141064159E-07"
        iyy="0.000248235159238422"
        iyz="7.93479798945356E-07"
        izz="0.000305121782839553" />
    </inertial>
    <visual>
      <origin
        xyz="0 0 0"
        rpy="0 0 0" />
      <geometry>
        <mesh
          filename="package://onero_description/meshes/A1_dual/Link_base_R.STL" />
      </geometry>
      <material
        name="">
        <color
          rgba="1 1 1 1" />
      </material>
    </visual>
    <collision>
      <origin
        xyz="0 0 0"
        rpy="0 0 0" />
      <geometry>
        <mesh
          filename="package://onero_description/meshes/A1_dual/Link_base_R.STL" />
      </geometry>
    </collision>
  </link>
  <joint
    name="joint_base_R"
    type="fixed">
    <origin
      xyz="0.00129998788592377 -0.0461696962244978 0.786817651368381"
      rpy="1.5707963267949 -1.5707963267949 0" />
    <parent
      link="base_link" />
    <child
      link="right_base_link" />
    <axis
      xyz="0 0 0" />
  </joint>
  <link
    name="right_link1">
    <inertial>
      <origin
        xyz="0.000528701384746212 0.000691059523307229 0.0930148088752137"
        rpy="0 0 0" />
      <mass
        value="0.445123480651538" />
      <inertia
        ixx="0.000620269005945169"
        ixy="-1.7829181721352E-07"
        ixz="1.39375528170229E-07"
        iyy="0.000515290876046097"
        iyz="-3.68477334539704E-05"
        izz="0.00025747618201433" />
    </inertial>
    <visual>
      <origin
        xyz="0 0 0"
        rpy="0 0 0" />
      <geometry>
        <mesh
          filename="package://onero_description/meshes/A1_dual/Link_R1.STL" />
      </geometry>
      <material
        name="">
        <color
          rgba="0.898039215686275 0.917647058823529 0.929411764705882 1" />
      </material>
    </visual>
    <collision>
      <origin
        xyz="0 0 0"
        rpy="0 0 0" />
      <geometry>
        <mesh
          filename="package://onero_description/meshes/A1_dual/Link_R1.STL" />
      </geometry>
    </collision>
  </link>
  <joint
    name="joint1-a1_r"
    type="revolute">
    <origin
      xyz="0 0 0.0125"
      rpy="0 0 0" />
    <parent
      link="right_base_link" />
    <child
      link="right_link1" />
    <axis
      xyz="0 0 1" />
    <limit
      lower="-1.04"
      upper="3.14"
      effort="0"
      velocity="0" />
  </joint>
  <link
    name="right_link2">
    <inertial>
      <origin
        xyz="-4.79251882686271E-05 -0.0610748205842253 0.00491189316430291"
        rpy="0 0 0" />
      <mass
        value="0.387804299075862" />
      <inertia
        ixx="0.000597196184278382"
        ixy="-8.33624572900867E-07"
        ixz="1.418887040585E-08"
        iyy="0.000348285614510568"
        iyz="-2.93681671030129E-05"
        izz="0.000403678012606387" />
    </inertial>
    <visual>
      <origin
        xyz="0 0 0"
        rpy="0 0 0" />
      <geometry>
        <mesh
          filename="package://onero_description/meshes/A1_dual/Link_R2.STL" />
      </geometry>
      <material
        name="">
        <color
          rgba="0.898039215686275 0.917647058823529 0.929411764705882 1" />
      </material>
    </visual>
    <collision>
      <origin
        xyz="0 0 0"
        rpy="0 0 0" />
      <geometry>
        <mesh
          filename="package://onero_description/meshes/A1_dual/Link_R2.STL" />
      </geometry>
    </collision>
  </link>
  <joint
    name="joint2-a1_r"
    type="revolute">
    <origin
      xyz="0 0 0.12744999999996"
      rpy="1.57079632679508 1.5707963267949 0" />
    <parent
      link="right_link1" />
    <child
      link="right_link2" />
    <axis
      xyz="0 0 1" />
    <limit
      lower="-3.14"
      upper="0.26"
      effort="0"
      velocity="0" />
  </joint>
  <link
    name="right_link3">
    <inertial>
      <origin
        xyz="-1.41791339719967E-05 -0.00178417845474385 0.109669668671437"
        rpy="0 0 0" />
      <mass
        value="0.407125793860475" />
      <inertia
        ixx="0.000446520666223513"
        ixy="-1.52102569119989E-08"
        ixz="-1.60234361204651E-07"
        iyy="0.000343044759489895"
        iyz="1.30123273479532E-05"
        izz="0.000286204871786059" />
    </inertial>
    <visual>
      <origin
        xyz="0 0 0"
        rpy="0 0 0" />
      <geometry>
        <mesh
          filename="package://onero_description/meshes/A1_dual/Link_R3.STL" />
      </geometry>
      <material
        name="">
        <color
          rgba="0.898039215686275 0.917647058823529 0.929411764705882 1" />
      </material>
    </visual>
    <collision>
      <origin
        xyz="0 0 0"
        rpy="0 0 0" />
      <geometry>
        <mesh
          filename="package://onero_description/meshes/A1_dual/Link_R3.STL" />
      </geometry>
    </collision>
  </link>
  <joint
    name="joint3-a1_r"
    type="revolute">
    <origin
      xyz="0 -0.0932500000000608 0"
      rpy="1.57079632679489 -1.5707963267949 0" />
    <parent
      link="right_link2" />
    <child
      link="right_link3" />
    <axis
      xyz="0 0 1" />
    <limit
      lower="-2.76"
      upper="2.76"
      effort="0"
      velocity="0" />
  </joint>
  <link
    name="right_link4">
    <inertial>
      <origin
        xyz="4.77747493508683E-07 -0.0625047132426329 0.00555704355217515"
        rpy="0 0 0" />
      <mass
        value="0.252142897287996" />
      <inertia
        ixx="0.000178779070302145"
        ixy="-6.97347608629508E-09"
        ixz="7.78466981652122E-10"
        iyy="0.000146134678627411"
        iyz="-3.30147349555166E-05"
        izz="0.000165597697715162" />
    </inertial>
    <visual>
      <origin
        xyz="0 0 0"
        rpy="0 0 0" />
      <geometry>
        <mesh
          filename="package://onero_description/meshes/A1_dual/Link_R4.STL" />
      </geometry>
      <material
        name="">
        <color
          rgba="0.898039215686275 0.917647058823529 0.929411764705882 1" />
      </material>
    </visual>
    <collision>
      <origin
        xyz="0 0 0"
        rpy="0 0 0" />
      <geometry>
        <mesh
          filename="package://onero_description/meshes/A1_dual/Link_R4.STL" />
      </geometry>
    </collision>
  </link>
  <joint
    name="joint4-a1_r"
    type="revolute">
    <origin
      xyz="0 0.000999999998782225 0.140250000000101"
      rpy="-1.5707963267895 0 0" />
    <parent
      link="right_link3" />
    <child
      link="right_link4" />
    <axis
      xyz="0 0 1" />
    <limit
      lower="-1.92"
      upper="1.92"
      effort="0"
      velocity="0" />
  </joint>
  <link
    name="right_link5">
    <inertial>
      <origin
        xyz="-2.15115908300036E-06 -0.000940016433332608 0.0983077058854084"
        rpy="0 0 0" />
      <mass
        value="0.333954018530655" />
      <inertia
        ixx="0.000324220055891183"
        ixy="-1.16857830776577E-09"
        ixz="7.2095952729132E-08"
        iyy="0.00029907861347288"
        iyz="-5.79215640631209E-06"
        izz="0.00016124141970014" />
    </inertial>
    <visual>
      <origin
        xyz="0 0 0"
        rpy="0 0 0" />
      <geometry>
        <mesh
          filename="package://onero_description/meshes/A1_dual/Link_R5.STL" />
      </geometry>
      <material
        name="">
        <color
          rgba="0.898039215686275 0.917647058823529 0.929411764705882 1" />
      </material>
    </visual>
    <collision>
      <origin
        xyz="0 0 0"
        rpy="0 0 0" />
      <geometry>
        <mesh
          filename="package://onero_description/meshes/A1_dual/Link_R5.STL" />
      </geometry>
    </collision>
  </link>
  <joint
    name="joint5-a1_r"
    type="revolute">
    <origin
      xyz="0 -0.0879999999845006 -0.000999999994519968"
      rpy="1.57079632680022 0 0" />
    <parent
      link="right_link4" />
    <child
      link="right_link5" />
    <axis
      xyz="0 0 1" />
    <limit
      lower="-2.23"
      upper="2.23"
      effort="0"
      velocity="0" />
  </joint>
  <link
    name="right_link6">
    <inertial>
      <origin
        xyz="1.41062096566495E-05 0.0616500031920713 0.00517126125253364"
        rpy="0 0 0" />
      <mass
        value="0.289938829856114" />
      <inertia
        ixx="0.00034657832636577"
        ixy="-3.69437698963052E-07"
        ixz="-1.71696816370923E-07"
        iyy="0.000183154986527696"
        iyz="3.25615224510484E-05"
        izz="0.000268358656569823" />
    </inertial>
    <visual>
      <origin
        xyz="0 0 0"
        rpy="0 0 0" />
      <geometry>
        <mesh
          filename="package://onero_description/meshes/A1_dual/Link_R6.STL" />
      </geometry>
      <material
        name="">
        <color
          rgba="1 1 1 1" />
      </material>
    </visual>
    <collision>
      <origin
        xyz="0 0 0"
        rpy="0 0 0" />
      <geometry>
        <mesh
          filename="package://onero_description/meshes/A1_dual/Link_R6.STL" />
      </geometry>
    </collision>
  </link>
  <joint
    name="joint6-a1_r"
    type="revolute">
    <origin
      xyz="0 -0.000500000006067092 0.13300000000003"
      rpy="1.57079632679516 0 0" />
    <parent
      link="right_link5" />
    <child
      link="right_link6" />
    <axis
      xyz="0 0 1" />
    <limit
      lower="-1.57"
      upper="1.57"
      effort="0"
      velocity="0" />
  </joint>
  <link
    name="right_link7">
    <inertial>
      <origin
        xyz="5.62946092910809E-10 -0.00220209359026055 0.00293052216882428"
        rpy="0 0 0" />
      <mass
        value="0.0177506427123713" />
      <inertia
        ixx="2.81905933094716E-06"
        ixy="5.7641533455085E-14"
        ixz="-2.02460067044014E-14"
        iyy="1.8945343219885E-06"
        iyz="2.22911768335107E-09"
        izz="4.6099418954554E-06" />
    </inertial>
    <visual>
      <origin
        xyz="0 0 0"
        rpy="0 0 0" />
      <geometry>
        <mesh
          filename="package://onero_description/meshes/A1_dual/Link_R7.STL" />
      </geometry>
      <material
        name="">
        <color
          rgba="0.898039215686275 0.917647058823529 0.929411764705882 1" />
      </material>
    </visual>
    <collision>
      <origin
        xyz="0 0 0"
        rpy="0 0 0" />
      <geometry>
        <mesh
          filename="package://onero_description/meshes/A1_dual/Link_R7.STL" />
      </geometry>
    </collision>
  </link>
  <joint
    name="joint7-a1_r"
    type="revolute">
    <origin
      xyz="0 0.111999999999958 -0.000500000000028034"
      rpy="1.5708 0 3.1416" />
    <parent
      link="right_link6" />
    <child
      link="right_link7" />
    <axis
      xyz="0 1 0" />
    <limit
      lower="-2.76"
      upper="2.76"
      effort="0"
      velocity="0" />
  </joint>
  <link
    name="left_base_link">
    <inertial>
      <origin
        xyz="-2.12826196715591E-05 5.52026218803445E-05 0.0171427754448579"
        rpy="0 0 0" />
      <mass
        value="0.401650168942009" />
      <inertia
        ixx="0.000237179758518644"
        ixy="1.22424408205499E-07"
        ixz="-1.57836402935085E-07"
        iyy="0.00024823611761246"
        iyz="-7.93541349372777E-07"
        izz="0.000305122605170233" />
    </inertial>
    <visual>
      <origin
        xyz="0 0 0"
        rpy="3.14159265358979 0 0" />
      <geometry>
        <mesh
          filename="package://onero_description/meshes/A1_dual/Link_base_L.STL" />
      </geometry>
      <material
        name="">
        <color
          rgba="0.776470588235294 0.756862745098039 0.737254901960784 1" />
      </material>
    </visual>
    <collision>
      <origin
        xyz="0 0 0"
        rpy="3.14159265358979 0 0" />
      <geometry>
        <mesh
          filename="package://onero_description/meshes/A1_dual/Link_base_L.STL" />
      </geometry>
    </collision>
  </link>
  <joint
    name="joint_base_l"
    type="fixed">
    <origin
      xyz="0.00129998788593704 0.0658303037755022 0.786817651368357"
      rpy="1.57079632679502 -1.5707963267949 0" />
    <parent
      link="base_link" />
    <child
      link="left_base_link" />
    <axis
      xyz="0 0 0" />
  </joint>
  <link
    name="left_link1">
    <inertial>
      <origin
        xyz="0.000104793909039569 -0.000878025489583305 0.0937688680157419"
        rpy="0 0 0" />
      <mass
        value="0.438675872181416" />
      <inertia
        ixx="0.00060517294321352"
        ixy="3.14143376862722E-07"
        ixz="-9.46425739217288E-07"
        iyy="0.000501491467720591"
        iyz="3.30016145254686E-05"
        izz="0.00025580993277449" />
    </inertial>
    <visual>
      <origin
        xyz="0 0 0"
        rpy="0 0 0" />
      <geometry>
        <mesh
          filename="package://onero_description/meshes/A1_dual/Link_L1.STL" />
      </geometry>
      <material
        name="">
        <color
          rgba="0.898039215686275 0.917647058823529 0.929411764705882 1" />
      </material>
    </visual>
    <collision>
      <origin
        xyz="0 0 0"
        rpy="0 0 0" />
      <geometry>
        <mesh
          filename="package://onero_description/meshes/A1_dual/Link_L1.STL" />
      </geometry>
    </collision>
  </link>
  <joint
    name="joint1-a1_l"
    type="revolute">
    <origin
      xyz="0 0 -0.01250000000001"
      rpy="3.14159265358979 0 0" />
    <parent
      link="left_base_link" />
    <child
      link="left_link1" />
    <axis
      xyz="0 0 1" />
    <limit
      lower="-3.14"
      upper="1.04"
      effort="0"
      velocity="0" />
  </joint>
  <link
    name="left_link2">
    <inertial>
      <origin
        xyz="-4.66303482248853E-05 0.0610765811025605 0.00481122218899703"
        rpy="0 0 0" />
      <mass
        value="0.387770755219132" />
      <inertia
        ixx="0.000597204372907025"
        ixy="8.3676342009039E-07"
        ixz="2.69873967537206E-08"
        iyy="0.000348292487571024"
        iyz="2.93717934653094E-05"
        izz="0.000403661570691348" />
    </inertial>
    <visual>
      <origin
        xyz="0 0 0"
        rpy="0 0 -3.14159265358979" />
      <geometry>
        <mesh
          filename="package://onero_description/meshes/A1_dual/Link_L2.STL" />
      </geometry>
      <material
        name="">
        <color
          rgba="0.898039215686275 0.917647058823529 0.929411764705882 1" />
      </material>
    </visual>
    <collision>
      <origin
        xyz="0 0 0"
        rpy="0 0 -3.14159265358979" />
      <geometry>
        <mesh
          filename="package://onero_description/meshes/A1_dual/Link_L2.STL" />
      </geometry>
    </collision>
  </link>
  <joint
    name="joint2-a1_l"
    type="revolute">
    <origin
      xyz="0 0 0.12744999999999"
      rpy="-1.57079632679478 -1.5707963267949 0" />
    <parent
      link="left_link1" />
    <child
      link="left_link2" />
    <axis
      xyz="0 0 1" />
    <limit
      lower="-0.26"
      upper="3.14"
      effort="0"
      velocity="0" />
  </joint>
  <link
    name="left_link3">
    <inertial>
      <origin
        xyz="1.43987309591519E-05 0.00178404133280444 0.109669668659996"
        rpy="0 0 0" />
      <mass
        value="0.407125793506889" />
      <inertia
        ixx="0.000446520666780017"
        ixy="-8.24275545731688E-09"
        ixz="1.61110520939149E-07"
        iyy="0.000343044757246363"
        iyz="-1.30123176926368E-05"
        izz="0.000286204871222088" />
    </inertial>
    <visual>
      <origin
        xyz="0 0 0"
        rpy="0 0 0" />
      <geometry>
        <mesh
          filename="package://onero_description/meshes/A1_dual/Link_L3.STL" />
      </geometry>
      <material
        name="">
        <color
          rgba="0.898039215686275 0.917647058823529 0.929411764705882 1" />
      </material>
    </visual>
    <collision>
      <origin
        xyz="0 0 0"
        rpy="0 0 0" />
      <geometry>
        <mesh
          filename="package://onero_description/meshes/A1_dual/Link_L3.STL" />
      </geometry>
    </collision>
  </link>
  <joint
    name="joint3-a1_l"
    type="revolute">
    <origin
      xyz="0 -0.0932499999999344 -0.000100000000084434"
      rpy="1.5707963267949 -1.5707963267949 0" />
    <parent
      link="left_link2" />
    <child
      link="left_link3" />
    <axis
      xyz="0 0 1" />
    <limit
      lower="-2.76"
      upper="2.76"
      effort="0"
      velocity="0" />
  </joint>
  <link
    name="left_link4">
    <inertial>
      <origin
        xyz="-9.99808131922229E-07 0.0625047132640995 0.00555704355349795"
        rpy="0 0 0" />
      <mass
        value="0.252142897202372" />
      <inertia
        ixx="0.000178779070280237"
        ixy="-6.97346977235617E-09"
        ixz="-7.78451594084039E-10"
        iyy="0.000146134678616042"
        iyz="3.30147349592292E-05"
        izz="0.000165597697680657" />
    </inertial>
    <visual>
      <origin
        xyz="0 0 0"
        rpy="0 0 0" />
      <geometry>
        <mesh
          filename="package://onero_description/meshes/A1_dual/Link_L4.STL" />
      </geometry>
      <material
        name="">
        <color
          rgba="0.898039215686275 0.917647058823529 0.929411764705882 1" />
      </material>
    </visual>
    <collision>
      <origin
        xyz="0 0 0"
        rpy="0 0 0" />
      <geometry>
        <mesh
          filename="package://onero_description/meshes/A1_dual/Link_L4.STL" />
      </geometry>
    </collision>
  </link>
  <joint
    name="joint4-a1_l"
    type="revolute">
    <origin
      xyz="0 -0.000999999996676215 0.140249999995695"
      rpy="1.57079632678358 0 6.73358220455809E-05" />
    <parent
      link="left_link3" />
    <child
      link="left_link4" />
    <axis
      xyz="0 0 1" />
    <limit
      lower="-1.92"
      upper="1.92"
      effort="0"
      velocity="0" />
  </joint>
  <link
    name="left_link5">
    <inertial>
      <origin
        xyz="2.18196075730452E-06 0.000940045309240328 0.0983077176130554"
        rpy="0 0 0" />
      <mass
        value="0.333953527048094" />
      <inertia
        ixx="0.000324219442352689"
        ixy="-1.17918293650099E-09"
        ixz="-7.21118252753774E-08"
        iyy="0.000299078218859742"
        iyz="5.79241839852753E-06"
        izz="0.000161241194938864" />
    </inertial>
    <visual>
      <origin
        xyz="0 0 0"
        rpy="0 0 0" />
      <geometry>
        <mesh
          filename="package://onero_description/meshes/A1_dual/Link_L5.STL" />
      </geometry>
      <material
        name="">
        <color
          rgba="0.898039215686275 0.917647058823529 0.929411764705882 1" />
      </material>
    </visual>
    <collision>
      <origin
        xyz="0 0 0"
        rpy="0 0 0" />
      <geometry>
        <mesh
          filename="package://onero_description/meshes/A1_dual/Link_L5.STL" />
      </geometry>
    </collision>
  </link>
  <joint
    name="joint5-a1_l"
    type="revolute">
    <origin
      xyz="0 0.08800000000195 -0.00100000000141642"
      rpy="-1.57079632679444 0 0" />
    <parent
      link="left_link4" />
    <child
      link="left_link5" />
    <axis
      xyz="0 0 1" />
    <limit
      lower="-2.23"
      upper="2.23"
      effort="0"
      velocity="0" />
  </joint>
  <link
    name="left_link6">
    <inertial>
      <origin
        xyz="-1.41083577817339E-05 -0.0616500007995244 0.00592126579529165"
        rpy="0 0 0" />
      <mass
        value="0.289938784030602" />
      <inertia
        ixx="0.000346578289751858"
        ixy="-3.69413598783459E-07"
        ixz="1.71707544035286E-07"
        iyy="0.000183154957190632"
        iyz="-3.25615027135764E-05"
        izz="0.000268358636842125" />
    </inertial>
    <visual>
      <origin
        xyz="0 0 0"
        rpy="0 0 0" />
      <geometry>
        <mesh
          filename="package://onero_description/meshes/A1_dual/Link_L6.STL" />
      </geometry>
      <material
        name="">
        <color
          rgba="1 1 1 1" />
      </material>
    </visual>
    <collision>
      <origin
        xyz="0 0 0"
        rpy="0 0 0" />
      <geometry>
        <mesh
          filename="package://onero_description/meshes/A1_dual/Link_L6.STL" />
      </geometry>
    </collision>
  </link>
  <joint
    name="joint6-a1_l"
    type="revolute">
    <origin
      xyz="0 0.000499999999968581 0.133000000000029"
      rpy="-1.57079632679557 0 0" />
    <parent
      link="left_link5" />
    <child
      link="left_link6" />
    <axis
      xyz="0 0 1" />
    <limit
      lower="-1.57"
      upper="1.57"
      effort="0"
      velocity="0" />
  </joint>
  <link
    name="left_link7">
    <inertial>
      <origin
        xyz="6.65807920271653E-10 -0.00220208936547997 0.00293052049190778"
        rpy="0 0 0" />
      <mass
        value="0.017750642712371" />
      <inertia
        ixx="2.81905933094713E-06"
        ixy="5.7633025928465E-14"
        ixz="-2.02477989966484E-14"
        iyy="1.89453432186468E-06"
        iyz="2.22904228611338E-09"
        izz="4.60994189557911E-06" />
    </inertial>
    <visual>
      <origin
        xyz="0 0 0"
        rpy="0 0 0" />
      <geometry>
        <mesh
          filename="package://onero_description/meshes/A1_dual/Link_L7.STL" />
      </geometry>
      <material
        name="">
        <color
          rgba="0.898039215686275 0.917647058823529 0.929411764705882 1" />
      </material>
    </visual>
    <collision>
      <origin
        xyz="0 0 0"
        rpy="0 0 0" />
      <geometry>
        <mesh
          filename="package://onero_description/meshes/A1_dual/Link_L7.STL" />
      </geometry>
    </collision>
  </link>
  <joint
    name="joint7-a1_l"
    type="revolute">
    <origin
      xyz="0 -0.11200000000003 0.000249999999859224"
      rpy="1.5708 6.7336E-05 0" />
    <parent
      link="left_link6" />
    <child
      link="left_link7" />
    <axis
      xyz="0 0 1" />
    <limit
      lower="-2.76"
      upper="2.76"
      effort="0"
      velocity="0" />
  </joint>
</robot>
