<mujoco model="A1_dual">
  <compiler angle="radian" meshdir="../../meshes/A1_dual/"/>

  <asset>
    <mesh name="base_link" content_type="model/stl" file="base_link.STL"/>
    <mesh name="Link_base_R" content_type="model/stl" file="Link_base_R.STL"/>
    <mesh name="Link_R1" content_type="model/stl" file="Link_R1.STL"/>
    <mesh name="Link_R2" content_type="model/stl" file="Link_R2.STL"/>
    <mesh name="Link_R3" content_type="model/stl" file="Link_R3.STL"/>
    <mesh name="Link_R4" content_type="model/stl" file="Link_R4.STL"/>
    <mesh name="Link_R5" content_type="model/stl" file="Link_R5.STL"/>
    <mesh name="Link_R6" content_type="model/stl" file="Link_R6.STL"/>
    <mesh name="Link_R7" content_type="model/stl" file="Link_R7.STL"/>
    <mesh name="Link_base_L" content_type="model/stl" file="Link_base_L.STL"/>
    <mesh name="Link_L1" content_type="model/stl" file="Link_L1.STL"/>
    <mesh name="Link_L2" content_type="model/stl" file="Link_L2.STL"/>
    <mesh name="Link_L3" content_type="model/stl" file="Link_L3.STL"/>
    <mesh name="Link_L4" content_type="model/stl" file="Link_L4.STL"/>
    <mesh name="Link_L5" content_type="model/stl" file="Link_L5.STL"/>
    <mesh name="Link_L6" content_type="model/stl" file="Link_L6.STL"/>
    <mesh name="Link_L7" content_type="model/stl" file="Link_L7.STL"/>
  </asset>

  <worldbody>
    <geom type="mesh" contype="0" conaffinity="0" group="1" density="0" rgba="0.776471 0.756863 0.737255 1" mesh="base_link"/>
    <geom type="mesh" rgba="0.776471 0.756863 0.737255 1" mesh="base_link"/>
    <geom pos="0.00129999 -0.0461697 0.786818" quat="0.5 0.5 -0.5 0.5" type="mesh" contype="0" conaffinity="0" group="1" density="0" rgba="1 1 1 1" mesh="Link_base_R"/>
    <geom pos="0.00129999 -0.0461697 0.786818" quat="0.5 0.5 -0.5 0.5" type="mesh" rgba="1 1 1 1" mesh="Link_base_R"/>
    <geom pos="0.00129999 0.0658303 0.786818" quat="-0.5 0.5 0.5 0.5" type="mesh" contype="0" conaffinity="0" group="1" density="0" rgba="0.776471 0.756863 0.737255 1" mesh="Link_base_L"/>
    <geom pos="0.00129999 0.0658303 0.786818" quat="-0.5 0.5 0.5 0.5" type="mesh" rgba="0.776471 0.756863 0.737255 1" mesh="Link_base_L"/>
    <body name="right_link1" pos="0.00129999 -0.0586697 0.786818" quat="0.5 0.5 -0.5 0.5">
      <inertial pos="0.000528701 0.00069106 0.0930148" quat="0.997578 -0.0695494 -0.00022182 -0.000968261" mass="0.445123" diaginertia="0.000620269 0.000520453 0.000252313"/>
      <joint name="joint1-a1_r" pos="0 0 0" axis="0 0 1" range="-1.04 3.14"/>
      <geom type="mesh" contype="0" conaffinity="0" group="1" density="0" rgba="0.898039 0.917647 0.929412 1" mesh="Link_R1"/>
      <geom type="mesh" rgba="0.898039 0.917647 0.929412 1" mesh="Link_R1"/>
      <body name="right_link2" pos="0 0 0.12745" quat="0.5 0.5 0.5 -0.5">
        <inertial pos="-4.79252e-05 -0.0610748 0.00491189" quat="0.549472 0.83551 -0.00159096 -0.000691922" mass="0.387804" diaginertia="0.000597199 0.000416349 0.000335612"/>
        <joint name="joint2-a1_r" pos="0 0 0" axis="0 0 1" range="-3.14 0.26"/>
        <geom type="mesh" contype="0" conaffinity="0" group="1" density="0" rgba="0.898039 0.917647 0.929412 1" mesh="Link_R2"/>
        <geom type="mesh" rgba="0.898039 0.917647 0.929412 1" mesh="Link_R2"/>
        <body name="right_link3" pos="0 -0.09325 0" quat="0.5 0.5 -0.5 0.5">
          <inertial pos="-1.41791e-05 -0.00178418 0.10967" quat="0.994244 0.107136 0.000493227 -0.000191692" mass="0.407126" diaginertia="0.000446521 0.000345882 0.000283367"/>
          <joint name="joint3-a1_r" pos="0 0 0" axis="0 0 1" range="-2.76 2.76"/>
          <geom type="mesh" contype="0" conaffinity="0" group="1" density="0" rgba="0.898039 0.917647 0.929412 1" mesh="Link_R3"/>
          <geom type="mesh" rgba="0.898039 0.917647 0.929412 1" mesh="Link_R3"/>
          <body name="right_link4" pos="0 0.001 0.14025" quat="0.707107 -0.707107 0 0">
            <inertial pos="4.77747e-07 -0.0625047 0.00555704" quat="0.316773 0.632348 -0.632112 0.316584" mass="0.252143" diaginertia="0.000190285 0.000178779 0.000121447"/>
            <joint name="joint4-a1_r" pos="0 0 0" axis="0 0 1" range="-1.92 1.92"/>
            <geom type="mesh" contype="0" conaffinity="0" group="1" density="0" rgba="0.898039 0.917647 0.929412 1" mesh="Link_R4"/>
            <geom type="mesh" rgba="0.898039 0.917647 0.929412 1" mesh="Link_R4"/>
            <body name="right_link5" pos="0 -0.088 -0.001" quat="0.707107 0.707107 0 0">
              <inertial pos="-2.15116e-06 -0.000940016 0.0983077" quat="0.99978 -0.02096 -0.000222224 -7.94843e-05" mass="0.333954" diaginertia="0.00032422 0.000299322 0.000160998"/>
              <joint name="joint5-a1_r" pos="0 0 0" axis="0 0 1" range="-2.23 2.23"/>
              <geom type="mesh" contype="0" conaffinity="0" group="1" density="0" rgba="0.898039 0.917647 0.929412 1" mesh="Link_R5"/>
              <geom type="mesh" rgba="0.898039 0.917647 0.929412 1" mesh="Link_R5"/>
              <body name="right_link6" pos="0 -0.0005 0.133" quat="0.707107 0.707107 0 0">
                <inertial pos="1.41062e-05 0.06165 0.00517126" quat="0.812566 0.582864 0.000531969 -0.00219186" mass="0.289939" diaginertia="0.00034658 0.000279376 0.000172136"/>
                <joint name="joint6-a1_r" pos="0 0 0" axis="0 0 1" range="-1.57 1.57"/>
                <geom type="mesh" contype="0" conaffinity="0" group="1" density="0" rgba="1 1 1 1" mesh="Link_R6"/>
                <geom type="mesh" rgba="1 1 1 1" mesh="Link_R6"/>
                <body name="right_link7" pos="0 0.112 -0.0005" quat="-2.59734e-06 -2.59735e-06 0.707108 0.707105">
                  <inertial pos="5.62946e-10 -0.00220209 0.00293052" quat="0.500205 0.499795 -0.499795 0.500205" mass="0.0177506" diaginertia="4.60994e-06 2.81906e-06 1.89453e-06"/>
                  <joint name="joint7-a1_r" pos="0 0 0" axis="0 1 0" range="-2.76 2.76"/>
                  <geom type="mesh" contype="0" conaffinity="0" group="1" density="0" rgba="0.898039 0.917647 0.929412 1" mesh="Link_R7"/>
                  <geom type="mesh" rgba="0.898039 0.917647 0.929412 1" mesh="Link_R7"/>
                </body>
              </body>
            </body>
          </body>
        </body>
      </body>
    </body>
    <body name="left_link1" pos="0.00129999 0.0783303 0.786818" quat="-0.5 0.5 0.5 0.5">
      <inertial pos="0.000104794 -0.000878025 0.0937689" quat="0.997847 0.0655693 0.00131951 0.00103307" mass="0.438676" diaginertia="0.000605176 0.000505847 0.000251451"/>
      <joint name="joint1-a1_l" pos="0 0 0" axis="0 0 1" range="-3.14 1.04"/>
      <geom type="mesh" contype="0" conaffinity="0" group="1" density="0" rgba="0.898039 0.917647 0.929412 1" mesh="Link_L1"/>
      <geom type="mesh" rgba="0.898039 0.917647 0.929412 1" mesh="Link_L1"/>
      <body name="left_link2" pos="0 0 0.12745" quat="0.5 -0.5 -0.5 -0.5">
        <inertial pos="-4.66303e-05 0.0610766 0.00481122" quat="0.835547 0.549416 0.000668583 0.00161871" mass="0.387771" diaginertia="0.000597207 0.000416339 0.000335612"/>
        <joint name="joint2-a1_l" pos="0 0 0" axis="0 0 1" range="-0.26 3.14"/>
        <geom quat="0 0 0 -1" type="mesh" contype="0" conaffinity="0" group="1" density="0" rgba="0.898039 0.917647 0.929412 1" mesh="Link_L2"/>
        <geom quat="0 0 0 -1" type="mesh" rgba="0.898039 0.917647 0.929412 1" mesh="Link_L2"/>
        <body name="left_link3" pos="0 -0.09325 -0.0001" quat="0.5 0.5 -0.5 0.5">
          <inertial pos="1.43987e-05 0.00178404 0.10967" quat="0.994244 -0.107136 -0.000496834 -0.000158219" mass="0.407126" diaginertia="0.000446521 0.000345882 0.000283367"/>
          <joint name="joint3-a1_l" pos="0 0 0" axis="0 0 1" range="-2.76 2.76"/>
          <geom type="mesh" contype="0" conaffinity="0" group="1" density="0" rgba="0.898039 0.917647 0.929412 1" mesh="Link_L3"/>
          <geom type="mesh" rgba="0.898039 0.917647 0.929412 1" mesh="Link_L3"/>
          <body name="left_link4" pos="0 -0.001 0.14025" quat="0.707107 0.707107 2.38068e-05 2.38068e-05">
            <inertial pos="-9.99808e-07 0.0625047 0.00555704" quat="0.632112 0.316584 -0.316773 0.632348" mass="0.252143" diaginertia="0.000190285 0.000178779 0.000121447"/>
            <joint name="joint4-a1_l" pos="0 0 0" axis="0 0 1" range="-1.92 1.92"/>
            <geom type="mesh" contype="0" conaffinity="0" group="1" density="0" rgba="0.898039 0.917647 0.929412 1" mesh="Link_L4"/>
            <geom type="mesh" rgba="0.898039 0.917647 0.929412 1" mesh="Link_L4"/>
            <body name="left_link5" pos="0 0.088 -0.001" quat="0.707107 -0.707107 0 0">
              <inertial pos="2.18196e-06 0.000940045 0.0983077" quat="0.99978 0.020961 0.000222276 -7.97128e-05" mass="0.333954" diaginertia="0.000324219 0.000299321 0.000160998"/>
              <joint name="joint5-a1_l" pos="0 0 0" axis="0 0 1" range="-2.23 2.23"/>
              <geom type="mesh" contype="0" conaffinity="0" group="1" density="0" rgba="0.898039 0.917647 0.929412 1" mesh="Link_L5"/>
              <geom type="mesh" rgba="0.898039 0.917647 0.929412 1" mesh="Link_L5"/>
              <body name="left_link6" pos="0 0.0005 0.133" quat="0.707107 -0.707107 0 0">
                <inertial pos="-1.41084e-05 -0.06165 0.00592127" quat="0.582864 0.812566 -0.00219183 0.000532041" mass="0.289939" diaginertia="0.00034658 0.000279376 0.000172136"/>
                <joint name="joint6-a1_l" pos="0 0 0" axis="0 0 1" range="-1.57 1.57"/>
                <geom type="mesh" contype="0" conaffinity="0" group="1" density="0" rgba="1 1 1 1" mesh="Link_L6"/>
                <geom type="mesh" rgba="1 1 1 1" mesh="Link_L6"/>
                <body name="left_link7" pos="0 -0.112 0.00025" quat="0.707105 0.707108 2.38068e-05 -2.38069e-05">
                  <inertial pos="6.65808e-10 -0.00220209 0.00293052" quat="0.500205 0.499795 -0.499795 0.500205" mass="0.0177506" diaginertia="4.60994e-06 2.81906e-06 1.89453e-06"/>
                  <joint name="joint7-a1_l" pos="0 0 0" axis="0 0 1" range="-2.76 2.76"/>
                  <geom type="mesh" contype="0" conaffinity="0" group="1" density="0" rgba="0.898039 0.917647 0.929412 1" mesh="Link_L7"/>
                  <geom type="mesh" rgba="0.898039 0.917647 0.929412 1" mesh="Link_L7"/>
                </body>
              </body>
            </body>
          </body>
        </body>
      </body>
    </body>
  </worldbody>
</mujoco>
